import unittest
import sys
import os
import time
import threading
from unittest.mock import patch, MagicMock, Mock

# Add project root to path
sys.path.insert(0, os.path.abspath(os.path.join(os.path.dirname(__file__), '../..')))

from fluxora.core.circuit_breaker import CircuitBreaker, CircuitState
from fluxora.core.retry import retry, RetryableError
from fluxora.core.fallback import DefaultValueFallback, with_fallback
from fluxora.core.transaction_coordinator import TransactionCoordinator, TransactionStatus

class TestErrorHandlingIntegration(unittest.TestCase):
    """
    Integration tests for error handling components working together
    """
    
    def test_circuit_breaker_with_retry_and_fallback(self):
        """Test that circuit breaker, retry, and fallback work together"""
        # Create a mock for tracking calls
        mock = Mock()
        
        # Create a fallback strategy
        fallback = DefaultValueFallback("fallback_result")
        
        # Create a circuit breaker
        circuit_breaker = CircuitBreaker(
            failure_threshold=3,
            recovery_timeout=0.1  # Short timeout for testing
        )
        
        # Define a function that will fail a few times then succeed
        @circuit_breaker
        @retry(max_attempts=2, retry_exceptions=RetryableError)
        @with_fallback(fallback)
        def unstable_service(fail_count=0):
            mock()
            if mock.call_count <= fail_count:
                raise RetryableError("Temporary failure")
            return "success"
        
        # Test with no failures
        result = unstable_service(fail_count=0)
        self.assertEqual(result, "success")
        self.assertEqual(mock.call_count, 1)
        mock.reset_mock()
        
        # Test with 1 failure (should retry and succeed)
        result = unstable_service(fail_count=1)
        self.assertEqual(result, "success")
        self.assertEqual(mock.call_count, 2)
        mock.reset_mock()
        
        # Test with 2 failures (should retry but fail, then use fallback)
        result = unstable_service(fail_count=2)
        self.assertEqual(result, "fallback_result")
        self.assertEqual(mock.call_count, 2)  # 2 attempts due to retry
        mock.reset_mock()
        
        # Test with 3 more failures to open the circuit
        for _ in range(3):
            result = unstable_service(fail_count=2)
            self.assertEqual(result, "fallback_result")
        
        # Verify the circuit is open
        self.assertEqual(circuit_breaker.state, CircuitState.OPEN)
        
        # Reset the mock to verify no more calls are made when circuit is open
        mock.reset_mock()
        
        # Test with circuit open (should use fallback without calling the function)
        result = unstable_service(fail_count=0)
        self.assertEqual(result, "fallback_result")
        mock.assert_not_called()
        
        # Wait for recovery timeout
        time.sleep(0.2)
        
        # Test after recovery timeout (circuit should be half-open)
        mock.reset_mock()
        result = unstable_service(fail_count=0)
        self.assertEqual(result, "success")
        mock.assert_called_once()
        
        # Verify the circuit is closed again
        self.assertEqual(circuit_breaker.state, CircuitState.CLOSED)

class TestTransactionWithErrorHandling(unittest.TestCase):
    """
    Integration tests for distributed transactions with error handling
    """
    
    def test_transaction_with_retry_and_circuit_breaker(self):
        """Test that transactions work with retry and circuit breaker"""
        # Create a transaction coordinator
        coordinator = TransactionCoordinator()
        
        # Create a mock for tracking calls
        mock = Mock()
        
        # Create a circuit breaker for the participant
        circuit_breaker = CircuitBreaker(
            failure_threshold=3,
            recovery_timeout=0.1  # Short timeout for testing
        )
        
        # Define a participant class with retry and circuit breaker
        class TestParticipant:
            def __init__(self, name, fail_prepare=False, fail_commit=False):
                self.name = name
                self.fail_prepare = fail_prepare
                self.fail_commit = fail_commit
                self.prepared_txns = set()
                self.committed_txns = set()
                self.aborted_txns = set()
            
            @circuit_breaker
            @retry(max_attempts=2, retry_exceptions=RetryableError)
            def prepare(self, transaction_id):
                mock(f"{self.name}_prepare")
                if self.fail_prepare:
                    raise RetryableError(f"{self.name} prepare failed")
                self.prepared_txns.add(transaction_id)
                return True
            
            @circuit_breaker
            @retry(max_attempts=2, retry_exceptions=RetryableError)
            def commit(self, transaction_id):
                mock(f"{self.name}_commit")
                if self.fail_commit:
                    raise RetryableError(f"{self.name} commit failed")
                if transaction_id not in self.prepared_txns:
                    return False
                self.committed_txns.add(transaction_id)
                return True
            
            @circuit_breaker
            def abort(self, transaction_id):
                mock(f"{self.name}_abort")
                self.aborted_txns.add(transaction_id)
                return True
        
        # Test successful transaction
        transaction_id = coordinator.create_transaction()
        participant1 = TestParticipant("p1")
        participant2 = TestParticipant("p2")
        
        coordinator.register_participant(transaction_id, participant1)
        coordinator.register_participant(transaction_id, participant2)
        
        result = coordinator.execute_transaction(transaction_id)
        self.assertTrue(result)
        self.assertEqual(coordinator.get_transaction_status(transaction_id), TransactionStatus.COMMITTED)
        
        # Verify participants were called correctly
        mock.assert_any_call("p1_prepare")
        mock.assert_any_call("p2_prepare")
        mock.assert_any_call("p1_commit")
        mock.assert_any_call("p2_commit")
        
        # Reset mock
        mock.reset_mock()
        
        # Test transaction with prepare failure (should abort)
        transaction_id = coordinator.create_transaction()
        participant1 = TestParticipant("p1")
        participant2 = TestParticipant("p2", fail_prepare=True)  # This one will fail
        
        coordinator.register_participant(transaction_id, participant1)
        coordinator.register_participant(transaction_id, participant2)
        
        result = coordinator.execute_transaction(transaction_id)
        self.assertFalse(result)
        self.assertEqual(coordinator.get_transaction_status(transaction_id), TransactionStatus.ABORTED)
        
        # Verify participants were called correctly
        mock.assert_any_call("p1_prepare")
        mock.assert_any_call("p2_prepare")  # Should be called twice due to retry
        mock.assert_any_call("p2_prepare")
        mock.assert_any_call("p1_abort")
        mock.assert_any_call("p2_abort")
        
        # Verify no commits were called
        self.assertNotIn("p1_commit", [call[0][0] for call in mock.call_args_list])
        self.assertNotIn("p2_commit", [call[0][0] for call in mock.call_args_list])

if __name__ == '__main__':
    unittest.main()
